# [JAVA - 점프 투 자바 #24] 

# 예외처리
```
자바 프로그램을 만들다 보면 수많은 예외 상황이 발생한다. 
예외 처리 방법을 알게 되면 보다 안전하고 유연한 프로그래밍을 만들 수 있다.
```
## 예외 예제 
```java
public class Sample {
    public static void main(String[] args){
        int c = 4 / 0;
    }
}
```
```
Exception in thread "main" java.lang.ArithmeticException: / by zero
    at Test.main(Test.java:14)
```
4를 0으로 나눌 수가 없으므로 이와 같이 산술에 문제가 생겼다는 ArithmeticException 예외가 발생한다.
## 예외 예제2
```java
public class Sample {
    public static void main(String[] args) {
        int[] a = {1, 2, 3};
        System.out.println(a[3]);
    }
}    
```
```
Exception in thread "main" java.lang.ArrayIndexOutOfBoundsException: 3
    at Test.main(Test.java:17)
```
a[3]은 a 배열의 4번째 값이므로 a 배열에서 구할 수 없다. 그래서 배열에서 아무것도 없는 곳을 가리켰다는 ArrayIndexOutOfBoundsException 예외가 발생했다.

## 예외 처리
```java
public class Sample {
    public static void main(String[] args) {
        int c;
        try {
            c = 4 / 0;
            System.out.print(c);
        } catch(ArithmeticException e) {
            c = -1;  // 예외가 발생하여 이 문장이 수행된다.
            System.out.print(c);
        }
    }
}
```
## finally
프로그램 수행 도중 예외가 발생하면 프로그램이 중지되거나 예외 처리에 의해 catch 구문이 실행된다.

어떤 예외가 발생하더라도 반드시 실행되어야 하는 부분이 있으면 finally를 사용한다.
```java
public class Sample {
    public void shouldBeRun() {
        System.out.println("ok thanks");
    }

    public static void main(String[] args) {
        Sample sample = new Sample();
        int c;
        try {
            c = 4 / 0;
        } catch (ArithmeticException e) {
            c = -1;
        } finally {
            sample.shouldBeRun();  // 예외에 상관없이 무조건 수행된다.
        }
    }
}

```